<?xml version='1.0' encoding='utf-8'?>
<robot name="asimov-1" mjcf_source="/home/shaw/eliza/eliza/packages/research/robot/assets/profiles/asimov-1/mjcf/asimov_eliza.xml" note="Generated from ASIMOV-1 MJCF; MuJoCo XML remains dynamics authority.">
  <link name="pelvis_link">
    <inertial>
      <origin xyz="-0.05409183232 -3.482595224e-05 -0.01562551822" rpy="0 0 0" />
      <mass value="3.50691251175897" />
      <inertia ixx="0.005521896904" ixy="4.558411644e-06" ixz="-7.802733884e-05" iyy="0.006266688203" iyz="1.101774672e-07" izz="0.005046553999" />
    </inertial>
    <visual name="pelvis_visual">
      <origin xyz="0 0 0" rpy="0 0 0" />
      <geometry>
        <mesh filename="meshes/IMU_ORIGIN.STL" />
      </geometry>
    </visual>
  </link>
  <link name="left_hip_pitch_link">
    <inertial>
      <origin xyz="0.001728954335 0.03605632625 0.0005692667395" rpy="0 0 0" />
      <mass value="1.05630112217695" />
      <inertia ixx="0.0006923298908" ixy="-3.576619614e-05" ixz="1.840033682e-06" iyy="0.000812587075" iyz="1.200314764e-05" izz="0.0007533801313" />
    </inertial>
    <visual name="left_hip_pitch_link_visual">
      <origin xyz="0 0 0" rpy="0 0 0" />
      <geometry>
        <mesh filename="meshes/LEFT_HIP_PITCH.STL" />
      </geometry>
    </visual>
  </link>
  <joint name="left_hip_pitch_joint" type="revolute">
    <parent link="pelvis_link" />
    <child link="left_hip_pitch_link" />
    <origin xyz="-0.052 0.0675 -0.044045" rpy="0 0 0" />
    <axis xyz="0 1 0" />
    <limit lower="-2.094395" upper="1" effort="20" velocity="20" />
  </joint>
  <link name="left_hip_roll_link">
    <inertial>
      <origin xyz="-0.01155413907 -0.0003348279462 -0.02941018527" rpy="0 0 0" />
      <mass value="0.414368139397033" />
      <inertia ixx="0.0002653940061" ixy="2.215143881e-06" ixz="-0.0001157810417" iyy="0.000357453871" iyz="2.984389288e-06" izz="0.0002344742715" />
    </inertial>
    <visual name="left_hip_roll_link_visual">
      <origin xyz="0 0 0" rpy="0 0 0" />
      <geometry>
        <mesh filename="meshes/LEFT_HIP_ROLL.STL" />
      </geometry>
    </visual>
  </link>
  <joint name="left_hip_roll_joint" type="revolute">
    <parent link="left_hip_pitch_link" />
    <child link="left_hip_roll_link" />
    <origin xyz="0.0422501 0.04000027594 0" rpy="0 0 0" />
    <axis xyz="1 0 0" />
    <limit lower="-0.785398" upper="0.785398" effort="20" velocity="20" />
  </joint>
  <link name="left_hip_yaw_link">
    <inertial>
      <origin xyz="0.00107948196 0.001024900749 -0.1203388591" rpy="0 0 0" />
      <mass value="1.86657016436158" />
      <inertia ixx="0.003416328058" ixy="1.128723441e-05" ixz="2.897790481e-05" iyy="0.003560159088" iyz="-0.0001197618954" izz="0.001375243721" />
    </inertial>
    <visual name="left_hip_yaw_link_visual">
      <origin xyz="0 0 0" rpy="0 0 0" />
      <geometry>
        <mesh filename="meshes/LEFT_HIP_YAW.STL" />
      </geometry>
    </visual>
  </link>
  <joint name="left_hip_yaw_joint" type="revolute">
    <parent link="left_hip_roll_link" />
    <child link="left_hip_yaw_link" />
    <origin xyz="-0.04225 0 -0.052" rpy="0 0 0" />
    <axis xyz="0 0 -1" />
    <limit lower="-0.785398" upper="0.785398" effort="20" velocity="20" />
  </joint>
  <link name="left_knee_link">
    <inertial>
      <origin xyz="-0.000500664455 0.0005092894895 -0.1126928877" rpy="0 0 0" />
      <mass value="2.39114151033076" />
      <inertia ixx="0.009621720602" ixy="9.876463922e-06" ixz="-0.000645140055" iyy="0.009753143566" iyz="-7.940581356e-06" izz="0.002330952369" />
    </inertial>
    <visual name="left_knee_link_visual">
      <origin xyz="0 0 0" rpy="0 0 0" />
      <geometry>
        <mesh filename="meshes/LEFT_KNEE.STL" />
      </geometry>
    </visual>
  </link>
  <joint name="left_knee_joint" type="revolute">
    <parent link="left_hip_yaw_link" />
    <child link="left_knee_link" />
    <origin xyz="0 0 -0.19564" rpy="0 0 0" />
    <axis xyz="0 1 0" />
    <limit lower="0" upper="1.5" effort="20" velocity="20" />
  </joint>
  <link name="left_ankle_pitch_link">
    <inertial>
      <origin xyz="-0.001179270406 -3.070191135e-08 -0.006176192354" rpy="0 0 0" />
      <mass value="0.273090119400173" />
      <inertia ixx="6.426613198e-05" ixy="-2.405731553e-10" ixz="-1.075345119e-06" iyy="8.099442114e-05" iyz="-2.305601048e-10" izz="4.719278413e-05" />
    </inertial>
    <visual name="left_ankle_pitch_link_visual">
      <origin xyz="0 0 0" rpy="0 0 0" />
      <geometry>
        <mesh filename="meshes/LEFT_ANKLE_A.STL" />
      </geometry>
    </visual>
  </link>
  <joint name="left_ankle_pitch_joint" type="revolute">
    <parent link="left_knee_link" />
    <child link="left_ankle_pitch_link" />
    <origin xyz="0 0 -0.2946623361" rpy="0 0 0" />
    <axis xyz="0 1 0" />
    <limit lower="-0.35" upper="0.35" effort="20" velocity="20" />
  </joint>
  <link name="left_ankle_roll_link">
    <inertial>
      <origin xyz="0.04274993813 0.001592573076 -0.01324506595" rpy="0 0 0" />
      <mass value="0.405640437504617" />
      <inertia ixx="0.000176487912" ixy="1.27462095e-05" ixz="-1.323273178e-05" iyy="0.0004133259112" iyz="5.53283536e-06" izz="0.000531913025" />
    </inertial>
    <visual name="left_ankle_roll_link_visual">
      <origin xyz="0 0 0" rpy="0 0 0" />
      <geometry>
        <mesh filename="meshes/LEFT_ANKLE_B.STL" />
      </geometry>
    </visual>
  </link>
  <joint name="left_ankle_roll_joint" type="revolute">
    <parent link="left_ankle_pitch_link" />
    <child link="left_ankle_roll_link" />
    <origin xyz="-0.0015 0 -0.009999992" rpy="0 0 0" />
    <axis xyz="-1 0 0" />
    <limit lower="-0.1" upper="0.1" effort="20" velocity="20" />
  </joint>
  <link name="left_toe_link">
    <inertial>
      <origin xyz="0.03201677738 0.000718248512 -0.0141312773" rpy="0 0 0" />
      <mass value="0.112221237946844" />
      <inertia ixx="5.535192522e-05" ixy="0" ixz="0" iyy="3.651308095e-05" iyz="0" izz="8.540299695e-05" />
    </inertial>
    <visual name="left_toe_link_visual">
      <origin xyz="0 0.008 0" rpy="0 0 0" />
      <geometry>
        <mesh filename="meshes/LEFT_TOE.STL" />
      </geometry>
    </visual>
  </link>
  <joint name="left_toe_joint" type="revolute">
    <parent link="left_ankle_roll_link" />
    <child link="left_toe_link" />
    <origin xyz="0.10253 -0.0043664 -0.0067324" rpy="0 0 0" />
    <axis xyz="0.010532 0.99994 0" />
    <limit lower="-1.047" upper="0" effort="5" velocity="10" />
  </joint>
  <link name="right_hip_pitch_link">
    <inertial>
      <origin xyz="0.00172891544 -0.03605607775 0.0005688308451" rpy="0 0 0" />
      <mass value="1.05629742879001" />
      <inertia ixx="0.0006923291362" ixy="3.576503727e-05" ixz="1.840998202e-06" iyy="0.0008125825587" iyz="-1.200753871e-05" izz="0.0007533841087" />
    </inertial>
    <visual name="right_hip_pitch_link_visual">
      <origin xyz="0 0 0" rpy="0 0 0" />
      <geometry>
        <mesh filename="meshes/RIGHT_HIP_PITCH.STL" />
      </geometry>
    </visual>
  </link>
  <joint name="right_hip_pitch_joint" type="revolute">
    <parent link="pelvis_link" />
    <child link="right_hip_pitch_link" />
    <origin xyz="-0.052 -0.0675 -0.044045" rpy="0 0 0" />
    <axis xyz="0 -1 0" />
    <limit lower="-1" upper="2.094395" effort="20" velocity="20" />
  </joint>
  <link name="right_hip_roll_link">
    <inertial>
      <origin xyz="-0.01154356737 0.0003614587139 -0.02938589083" rpy="0 0 0" />
      <mass value="0.414825000619808" />
      <inertia ixx="0.0002658932272" ixy="-2.331358933e-06" ixz="-0.0001158839661" iyy="0.0003577347501" iyz="-3.2326209e-06" izz="0.0002348039242" />
    </inertial>
    <visual name="right_hip_roll_link_visual">
      <origin xyz="0 0 0" rpy="0 0 0" />
      <geometry>
        <mesh filename="meshes/RIGHT_HIP_ROLL.STL" />
      </geometry>
    </visual>
  </link>
  <joint name="right_hip_roll_joint" type="revolute">
    <parent link="right_hip_pitch_link" />
    <child link="right_hip_roll_link" />
    <origin xyz="0.04225 -0.04 0" rpy="0 0 0" />
    <axis xyz="1 0 0" />
    <limit lower="-0.785398" upper="0.785398" effort="20" velocity="20" />
  </joint>
  <link name="right_hip_yaw_link">
    <inertial>
      <origin xyz="0.00107595248 -0.001021764996 -0.120345116" rpy="0 0 0" />
      <mass value="1.86647220449567" />
      <inertia ixx="0.003415887345" ixy="-1.175977833e-05" ixz="2.917335953e-05" iyy="0.003559900155" iyz="0.0001197156713" izz="0.001375252722" />
    </inertial>
    <visual name="right_hip_yaw_link_visual">
      <origin xyz="0 0 0" rpy="0 0 0" />
      <geometry>
        <mesh filename="meshes/RIGHT_HIP_YAW.STL" />
      </geometry>
    </visual>
  </link>
  <joint name="right_hip_yaw_joint" type="revolute">
    <parent link="right_hip_roll_link" />
    <child link="right_hip_yaw_link" />
    <origin xyz="-0.04225 0 -0.052" rpy="0 0 0" />
    <axis xyz="0 0 -1" />
    <limit lower="-0.785398" upper="0.785398" effort="20" velocity="20" />
  </joint>
  <link name="right_knee_link">
    <inertial>
      <origin xyz="-0.0004975872337 -0.0004147572249 -0.1126926936" rpy="0 0 0" />
      <mass value="2.39110172735043" />
      <inertia ixx="0.009621482138" ixy="-9.875278239e-06" ixz="-0.0006450947183" iyy="0.00975287238" iyz="7.984313674e-06" izz="0.002330903583" />
    </inertial>
    <visual name="right_knee_link_visual">
      <origin xyz="0 0 0" rpy="0 0 0" />
      <geometry>
        <mesh filename="meshes/RIGHT_KNEE.STL" />
      </geometry>
    </visual>
  </link>
  <joint name="right_knee_joint" type="revolute">
    <parent link="right_hip_yaw_link" />
    <child link="right_knee_link" />
    <origin xyz="0 0 -0.19564" rpy="0 0 0" />
    <axis xyz="0 -1 0" />
    <limit lower="-1.5" upper="0" effort="20" velocity="20" />
  </joint>
  <link name="right_ankle_pitch_link">
    <inertial>
      <origin xyz="-0.00117936926 6.867168649e-08 -0.006176145828" rpy="0 0 0" />
      <mass value="0.27308917159726" />
      <inertia ixx="6.426594521e-05" ixy="-1.022813458e-10" ixz="-1.075587701e-06" iyy="8.099443484e-05" iyz="3.527011844e-10" izz="4.719260128e-05" />
    </inertial>
    <visual name="right_ankle_pitch_link_visual">
      <origin xyz="0 0 0" rpy="0 0 0" />
      <geometry>
        <mesh filename="meshes/RIGHT_ANKLE_A.STL" />
      </geometry>
    </visual>
  </link>
  <joint name="right_ankle_pitch_joint" type="revolute">
    <parent link="right_knee_link" />
    <child link="right_ankle_pitch_link" />
    <origin xyz="0 0.0001 -0.2946623361" rpy="0 0 0" />
    <axis xyz="0 -1 0" />
    <limit lower="-0.35" upper="0.35" effort="20" velocity="20" />
  </joint>
  <link name="right_ankle_roll_link">
    <inertial>
      <origin xyz="0.03760462407 -0.00113270119 -0.01206675198" rpy="0 0 0" />
      <mass value="0.405640437504617" />
      <inertia ixx="0.0001864220342" ixy="-1.268263551e-05" ixz="-1.313471744e-05" iyy="0.0004161542882" iyz="-5.519847575e-06" izz="0.0005383165152" />
    </inertial>
    <visual name="right_ankle_roll_link_visual">
      <origin xyz="0 0 0" rpy="0 0 0" />
      <geometry>
        <mesh filename="meshes/RIGHT_ANKLE_B.STL" />
      </geometry>
    </visual>
  </link>
  <joint name="right_ankle_roll_joint" type="revolute">
    <parent link="right_ankle_pitch_link" />
    <child link="right_ankle_roll_link" />
    <origin xyz="-0.0015 0 -0.009999992" rpy="0 0 0" />
    <axis xyz="-1 0 0" />
    <limit lower="-0.1" upper="0.1" effort="20" velocity="20" />
  </joint>
  <link name="right_toe_link">
    <inertial>
      <origin xyz="0.03201417544 -0.0008167080131 -0.01413090946" rpy="0 0 0" />
      <mass value="0.112221754054884" />
      <inertia ixx="5.53589487e-05" ixy="0" ixz="0" iyy="3.6505277e-05" iyz="0" izz="8.540173571e-05" />
    </inertial>
    <visual name="right_toe_link_visual">
      <origin xyz="0 -0.008 0" rpy="0 0 0" />
      <geometry>
        <mesh filename="meshes/RIGHT_TOE.STL" />
      </geometry>
    </visual>
  </link>
  <joint name="right_toe_joint" type="revolute">
    <parent link="right_ankle_roll_link" />
    <child link="right_toe_link" />
    <origin xyz="0.10247 0.0042796 -0.0067324" rpy="0 0 0" />
    <axis xyz="0.0074685 -0.99997 0" />
    <limit lower="0" upper="1.047" effort="5" velocity="10" />
  </joint>
  <link name="waist_yaw_link">
    <inertial>
      <origin xyz="-0.006993936367 -2.508121256e-05 0.204039878" rpy="0 0 0" />
      <mass value="8.20850158063177" />
      <inertia ixx="0.04981397107" ixy="-2.411153088e-05" ixz="0.003192305044" iyy="0.0397024418" iyz="-1.460929099e-05" izz="0.03212665803" />
    </inertial>
    <visual name="waist_yaw_link_visual">
      <origin xyz="0 0 0" rpy="0 0 0" />
      <geometry>
        <mesh filename="meshes/WAIST_YAW.STL" />
      </geometry>
    </visual>
  </link>
  <joint name="waist_yaw_joint" type="revolute">
    <parent link="pelvis_link" />
    <child link="waist_yaw_link" />
    <origin xyz="-0.052 0 0.074755" rpy="0 0 0" />
    <axis xyz="0 0 1" />
    <limit lower="-1.570796" upper="1.570796" effort="20" velocity="20" />
  </joint>
  <link name="neck_yaw_link">
    <inertial>
      <origin xyz="-0.0002321550494 -0.0006869323888 0.03567468417" rpy="0 0 0" />
      <mass value="0.53278930532821" />
      <inertia ixx="0.000264347243" ixy="-3.484135137e-12" ixz="1.212626814e-05" iyy="0.0002487715643" iyz="-8.873647228e-11" izz="0.0002019309198" />
    </inertial>
    <visual name="neck_yaw_link_visual">
      <origin xyz="0 0 0" rpy="0 0 0" />
      <geometry>
        <mesh filename="meshes/NECK_YAW.STL" />
      </geometry>
    </visual>
  </link>
  <joint name="neck_yaw_joint" type="revolute">
    <parent link="waist_yaw_link" />
    <child link="neck_yaw_link" />
    <origin xyz="-0.01659877455 0 0.3781670296" rpy="0 0 0" />
    <axis xyz="0 0 1" />
    <limit lower="-1.570796" upper="1.570796" effort="20" velocity="20" />
  </joint>
  <link name="neck_pitch_link">
    <inertial>
      <origin xyz="0.01238877547 0.0008619521156 0.04251892729" rpy="0 0 0" />
      <mass value="0.394055609177456" />
      <inertia ixx="0.001287267119" ixy="3.551753115e-07" ixz="0.0001425546374" iyy="0.001730870704" iyz="-3.997831799e-07" izz="0.00145145415" />
    </inertial>
    <visual name="neck_pitch_link_visual">
      <origin xyz="0 0 0" rpy="0 0 0" />
      <geometry>
        <mesh filename="meshes/NECK_PITCH.STL" />
      </geometry>
    </visual>
  </link>
  <joint name="neck_pitch_joint" type="revolute">
    <parent link="neck_yaw_link" />
    <child link="neck_pitch_link" />
    <origin xyz="0 0 0.03735" rpy="0 0 0" />
    <axis xyz="0 1 0" />
    <limit lower="-0.785398" upper="0.785398" effort="20" velocity="20" />
  </joint>
  <link name="right_shoulder_pitch_link">
    <inertial>
      <origin xyz="0.000129810971 -0.01579218297 -1.886169192e-05" rpy="0 0 0" />
      <mass value="0.599156105726411" />
      <inertia ixx="0.0003303181508" ixy="-2.568852685e-07" ixz="2.440637577e-09" iyy="0.0004185132624" iyz="-3.986644146e-10" izz="0.0004213841436" />
    </inertial>
    <visual name="right_shoulder_pitch_link_visual">
      <origin xyz="0 0 0" rpy="0 0 0" />
      <geometry>
        <mesh filename="meshes/RIGHT_SHOULDER_PITCH.STL" />
      </geometry>
    </visual>
  </link>
  <joint name="right_shoulder_pitch_joint" type="revolute">
    <parent link="waist_yaw_link" />
    <child link="right_shoulder_pitch_link" />
    <origin xyz="-0.02621282535 -0.0965 0.2611404833" rpy="0 0 0" />
    <axis xyz="0 -1 0" />
    <limit lower="-0.872665" upper="3.141593" effort="20" velocity="20" />
  </joint>
  <link name="right_shoulder_roll_link">
    <inertial>
      <origin xyz="0.0001141776248 -4.351421458e-05 -0.03731006897" rpy="0 0 0" />
      <mass value="1.31322237625579" />
      <inertia ixx="0.001632804646" ixy="4.422950386e-07" ixz="9.017972571e-07" iyy="0.001491484773" iyz="3.090767038e-06" izz="0.0007407853478" />
    </inertial>
    <visual name="right_shoulder_roll_link_visual">
      <origin xyz="0 0 0" rpy="0 0 0" />
      <geometry>
        <mesh filename="meshes/RIGHT_SHOULDER_ROLL.STL" />
      </geometry>
    </visual>
  </link>
  <joint name="right_shoulder_roll_joint" type="revolute">
    <parent link="right_shoulder_pitch_link" />
    <child link="right_shoulder_roll_link" />
    <origin xyz="0 -0.06535322323 -6.334135041e-05" rpy="0 0 0" />
    <axis xyz="-1 0 0" />
    <limit lower="0" upper="1.570796" effort="20" velocity="20" />
  </joint>
  <link name="right_shoulder_yaw_link">
    <inertial>
      <origin xyz="-0.0003250661224 0.0003205039551 -0.0759404985" rpy="0 0 0" />
      <mass value="0.712261755331765" />
      <inertia ixx="0.0005026643424" ixy="1.038748269e-07" ixz="3.848986797e-07" iyy="0.0005162594955" iyz="-9.284062409e-07" izz="0.0003106780038" />
    </inertial>
    <visual name="right_shoulder_yaw_link_visual">
      <origin xyz="0 0 0" rpy="0 0 0" />
      <geometry>
        <mesh filename="meshes/RIGHT_SHOULDER_YAW.STL" />
      </geometry>
    </visual>
  </link>
  <joint name="right_shoulder_yaw_joint" type="revolute">
    <parent link="right_shoulder_roll_link" />
    <child link="right_shoulder_yaw_link" />
    <origin xyz="0 0 -0.12899875" rpy="0 0 0" />
    <axis xyz="0 0 -1" />
    <limit lower="-1.570796" upper="1.570796" effort="20" velocity="20" />
  </joint>
  <link name="right_elbow_link">
    <inertial>
      <origin xyz="0.05237559854 -9.843042283e-05 -0.04444259118" rpy="0 0 0" />
      <mass value="0.662314258886328" />
      <inertia ixx="0.0003317099774" ixy="1.143787702e-07" ixz="5.587067574e-05" iyy="0.0004184328786" iyz="-9.740426844e-08" izz="0.0003678169223" />
    </inertial>
    <visual name="right_elbow_link_visual">
      <origin xyz="0 0 0" rpy="0 0 0" />
      <geometry>
        <mesh filename="meshes/RIGHT_ELBOW.STL" />
      </geometry>
    </visual>
  </link>
  <joint name="right_elbow_joint" type="revolute">
    <parent link="right_shoulder_yaw_link" />
    <child link="right_elbow_link" />
    <origin xyz="0 0 -0.0966013" rpy="0 0 0" />
    <axis xyz="0 1 0" />
    <limit lower="-2.443461" upper="0" effort="20" velocity="20" />
  </joint>
  <link name="right_wrist_yaw_link">
    <inertial>
      <origin xyz="0.003822891292 8.36540312e-09 -0.003207785857" rpy="0 0 0" />
      <mass value="0.0580595106779709" />
      <inertia ixx="1.188030017e-05" ixy="3.737968677e-08" ixz="-3.063460189e-06" iyy="8.854608036e-06" iyz="4.454234307e-08" izz="1.079993917e-05" />
    </inertial>
    <visual name="right_wrist_yaw_link_visual">
      <origin xyz="0 0 0" rpy="0 0 0" />
      <geometry>
        <mesh filename="meshes/RIGHT_WRIST_YAW.STL" />
      </geometry>
    </visual>
  </link>
  <joint name="right_wrist_yaw_joint" type="revolute">
    <parent link="right_elbow_link" />
    <child link="right_wrist_yaw_link" />
    <origin xyz="0.08656302207 0 -0.07263499989" rpy="0 0 0" />
    <axis xyz="0.7660444431 0 -0.6427876097" />
    <limit lower="-3.141593" upper="3.141593" effort="20" velocity="20" />
  </joint>
  <link name="left_shoulder_pitch_link">
    <inertial>
      <origin xyz="0.0001598894835 0.01579158744 -3.482031877e-07" rpy="0 0 0" />
      <mass value="0.599157136550892" />
      <inertia ixx="0.0003303159213" ixy="2.455356997e-07" ixz="-2.283631785e-09" iyy="0.0004185178584" iyz="-1.018548534e-08" izz="0.0004213791655" />
    </inertial>
    <visual name="left_shoulder_pitch_link_visual">
      <origin xyz="0 0 0" rpy="0 0 0" />
      <geometry>
        <mesh filename="meshes/LEFT_SHOULDER_PITCH.STL" />
      </geometry>
    </visual>
  </link>
  <joint name="left_shoulder_pitch_joint" type="revolute">
    <parent link="waist_yaw_link" />
    <child link="left_shoulder_pitch_link" />
    <origin xyz="-0.02621282535 0.0965 0.2611404833" rpy="0 0 0" />
    <axis xyz="0 1 0" />
    <limit lower="-3.141593" upper="0.872665" effort="20" velocity="20" />
  </joint>
  <link name="left_shoulder_roll_link">
    <inertial>
      <origin xyz="0.0001140183876 4.32880672e-05 -0.03731005975" rpy="0 0 0" />
      <mass value="1.3132281302001" />
      <inertia ixx="0.001632813644" ixy="-4.363223112e-07" ixz="9.066462214e-07" iyy="0.001491474896" iyz="-3.084593145e-06" izz="0.0007408097904" />
    </inertial>
    <visual name="left_shoulder_roll_link_visual">
      <origin xyz="0 0 0" rpy="0 0 0" />
      <geometry>
        <mesh filename="meshes/LEFT_SHOULDER_ROLL.STL" />
      </geometry>
    </visual>
  </link>
  <joint name="left_shoulder_roll_joint" type="revolute">
    <parent link="left_shoulder_pitch_link" />
    <child link="left_shoulder_roll_link" />
    <origin xyz="0.0001 0.06535322323 0" rpy="0 0 0" />
    <axis xyz="-1 0 0" />
    <limit lower="-1.570796" upper="0" effort="20" velocity="20" />
  </joint>
  <link name="left_shoulder_yaw_link">
    <inertial>
      <origin xyz="-0.0003300006362 0.0001360367151 -0.07536191018" rpy="0 0 0" />
      <mass value="0.712261755331765" />
      <inertia ixx="0.0005013958201" ixy="-1.035724302e-07" ixz="3.857240017e-07" iyy="0.0005146327974" iyz="9.789699759e-07" izz="0.000310276967" />
    </inertial>
    <visual name="left_shoulder_yaw_link_visual">
      <origin xyz="0 0 0" rpy="0 0 0" />
      <geometry>
        <mesh filename="meshes/LEFT_SHOULDER_YAW.STL" />
      </geometry>
    </visual>
  </link>
  <joint name="left_shoulder_yaw_joint" type="revolute">
    <parent link="left_shoulder_roll_link" />
    <child link="left_shoulder_yaw_link" />
    <origin xyz="0 0 -0.12899875" rpy="0 0 0" />
    <axis xyz="0 0 -1" />
    <limit lower="-1.570796" upper="1.570796" effort="20" velocity="20" />
  </joint>
  <link name="left_elbow_link">
    <inertial>
      <origin xyz="0.0523756419 9.847233483e-05 -0.04444264251" rpy="0 0 0" />
      <mass value="0.662317601299901" />
      <inertia ixx="0.0003317095185" ixy="-1.152654524e-07" ixz="5.587342465e-05" iyy="0.0004184302982" iyz="9.677953854e-08" izz="0.0003678178442" />
    </inertial>
    <visual name="left_elbow_link_visual">
      <origin xyz="0 0 0" rpy="0 0 0" />
      <geometry>
        <mesh filename="meshes/LEFT_ELBOW.STL" />
      </geometry>
    </visual>
  </link>
  <joint name="left_elbow_joint" type="revolute">
    <parent link="left_shoulder_yaw_link" />
    <child link="left_elbow_link" />
    <origin xyz="0 0 -0.0963013" rpy="0 0 0" />
    <axis xyz="0 -1 0" />
    <limit lower="0" upper="2.443461" effort="20" velocity="20" />
  </joint>
  <link name="left_wrist_yaw_link">
    <inertial>
      <origin xyz="0.003822893244 1.739445296e-08 -0.003207742037" rpy="0 0 0" />
      <mass value="0.058058790654763" />
      <inertia ixx="1.20674298e-05" ixy="1.833353459e-07" ixz="-2.840253656e-06" iyy="8.401301399e-06" iyz="2.184793015e-07" izz="1.106580349e-05" />
    </inertial>
    <visual name="left_wrist_yaw_link_visual">
      <origin xyz="0 0 0" rpy="0 0 0" />
      <geometry>
        <mesh filename="meshes/LEFT_WRIST_YAW.STL" />
      </geometry>
    </visual>
  </link>
  <joint name="left_wrist_yaw_joint" type="revolute">
    <parent link="left_elbow_link" />
    <child link="left_wrist_yaw_link" />
    <origin xyz="0.08656302208 0 -0.07263499989" rpy="0 0 0" />
    <axis xyz="0.7660444431 0 -0.6427876097" />
    <limit lower="-3.141593" upper="3.141593" effort="20" velocity="20" />
  </joint>
  <!--links=28 joints=27 visuals=28-->
</robot>